import { describe, it, expect, vi } from 'vitest';
import { render, screen, fireEvent } from '@testing-library/react';
import ErrorBoundary from '../components/ErrorBoundary';

// Component that throws an error
const ThrowError: React.FC<{ shouldThrow?: boolean }> = ({ shouldThrow = true }) => {
  if (shouldThrow) {
    throw new Error('Test error');
  }
  return <div>No error</div>;
};

// Mock console methods
const consoleMock = {
  error: vi.fn(),
};
Object.defineProperty(console, 'error', { value: consoleMock.error });

describe('ErrorBoundary', () => {
  beforeEach(() => {
    vi.clearAllMocks();
  });

  it('should render children when there is no error', () => {
    render(
      <ErrorBoundary>
        <ThrowError shouldThrow={false} />
      </ErrorBoundary>
    );

    expect(screen.getByText('No error')).toBeInTheDocument();
  });

  it('should render error UI when child component throws', () => {
    render(
      <ErrorBoundary>
        <ThrowError />
      </ErrorBoundary>
    );

    expect(screen.getByText('Something went wrong')).toBeInTheDocument();
    expect(screen.getByText(/This widget encountered an error/)).toBeInTheDocument();
    expect(screen.getByRole('button', { name: 'Try Again' })).toBeInTheDocument();
    expect(screen.getByRole('button', { name: 'Reload Page' })).toBeInTheDocument();
  });

  it('should call onError callback when error occurs', () => {
    const onError = vi.fn();

    render(
      <ErrorBoundary onError={onError}>
        <ThrowError />
      </ErrorBoundary>
    );

    expect(onError).toHaveBeenCalledWith(
      expect.any(Error),
      expect.objectContaining({
        componentStack: expect.any(String),
      })
    );
  });

  it('should render custom fallback when provided', () => {
    const customFallback = <div>Custom error message</div>;

    render(
      <ErrorBoundary fallback={customFallback}>
        <ThrowError />
      </ErrorBoundary>
    );

    expect(screen.getByText('Custom error message')).toBeInTheDocument();
    expect(screen.queryByText('Something went wrong')).not.toBeInTheDocument();
  });

  it('should have Try Again button that calls resetErrorBoundary', () => {
    render(
      <ErrorBoundary>
        <ThrowError />
      </ErrorBoundary>
    );

    expect(screen.getByText('Something went wrong')).toBeInTheDocument();

    const tryAgainButton = screen.getByRole('button', { name: 'Try Again' });
    expect(tryAgainButton).toBeInTheDocument();
    
    // Just verify the button exists and is clickable
    fireEvent.click(tryAgainButton);
    // The error boundary should still show the error since the child still throws
    expect(screen.getByText('Something went wrong')).toBeInTheDocument();
  });

  it('should show error details in development mode', () => {
    const originalEnv = process.env.NODE_ENV;
    process.env.NODE_ENV = 'development';

    render(
      <ErrorBoundary>
        <ThrowError />
      </ErrorBoundary>
    );

    expect(screen.getByText('Show error details')).toBeInTheDocument();

    // Cleanup
    process.env.NODE_ENV = originalEnv;
  });

  it('should reset when resetKeys change', () => {
    let resetKey = 'key1';
    
    const { rerender } = render(
      <ErrorBoundary resetKeys={[resetKey]}>
        <ThrowError />
      </ErrorBoundary>
    );

    expect(screen.getByText('Something went wrong')).toBeInTheDocument();

    // Change reset key and rerender with non-throwing component
    resetKey = 'key2';
    rerender(
      <ErrorBoundary resetKeys={[resetKey]}>
        <ThrowError shouldThrow={false} />
      </ErrorBoundary>
    );

    expect(screen.getByText('No error')).toBeInTheDocument();
  });
});